Workbook
Name balance_type: 1
Name calc: 1
Name co: 100
Name Codici: #REF!
Name DATOS: [3]VALRET!$C$9:$AV$120
Name FY: 2004
Name HOJA: '[4]HOJA DE DATOS'!$C$6:$R$121
Name howToChange: #REF!
Name howToChange: #REF!
Name howToChange: #REF!
Name howToCheck: #REF!
Name howToCheck: #REF!
Name howToCheck: #REF!
Name LOLD: 1
Name LOLD_Table: 120
Name NIF_DEALER: [5]Dealers!$C:$C
Name NOMBRE_DEALER: [5]Dealers!$A:$A
Name ORDINI_ATTIVI_YTD: #REF!
Name period: 12
Name round: 1
Name Stop: "Objet 33"
Name TA_2002: #REF!
Name TA_2002: #REF!
Name TA_2002: #REF!
Name TA_GLOBAL: #REF!
Name TA_GLOBAL: #REF!
Name TA_GLOBAL: #REF!
Name TABLEAUENCOURS: #REF!
Name TABLEAUENCOURS: #REF!
Name TABLEAUENCOURS: #REF!
Name value: 3
Name versionno: 1

Sheet sint HQ
B3: Company | C3: LINDE MATERIAL HANDLING VERONA S.P.A. | H3: MAIN RATIO
B4: in loc. currency/000 | C4: =+'CEE view'!C2 -> 2022 | D4: =+'CEE view'!D2 -> 2023 | E4: =+'CEE view'!E2 -> 2024 | F4: D | I4: =+C4 -> 2022 | J4: =+D4 -> 2023 | K4: =+E4 -> 2024
B5: Total sales | C5: =+'CEE view'!C84 -> 20727.579 | D5: =+'CEE view'!D84 -> 22640.669 | E5: =+'CEE view'!E84 -> 20375.419 | F5: =+IF(D5*E5<=0,"N.S",IF(AND(E5*D5>0,E5<0),-(E5-D5)/D5,(E5-D5)/D5)) -> -0.10005226 | H5: D/E | I5: =+'CEE view'!C106 -> 0.014058641 | J5: =+'CEE view'!D106 -> 0.011932601 | K5: =+'CEE view'!E106 -> -0.00015634015
B6: EBITDA | C6: =+'CEE view'!C92 -> 1605.692 | D6: =+'CEE view'!D92 -> 2385.336 | E6: =+'CEE view'!E92 -> 1907.317 | F6: =+IF(D6*E6<=0,"N.S",IF(AND(E6*D6>0,E6<0),-(E6-D6)/D6,(E6-D6)/D6)) -> -0.20039902 | H6: Equity Ratio | I6: =+'CEE view'!C108 -> 0.26234006 | J6: =+'CEE view'!D108 -> 0.25749024 | K6: =+'CEE view'!E108 -> 0.39415763
B7: Interest Expenses | C7: =-'input CEE'!B133/1000 -> -0.446 | D7: =-'input CEE'!C133/1000 -> -9.737 | E7: =-'input CEE'!D133/1000 -> -66.947 | F7: =+IF(D7*E7<=0,"N.S",IF(AND(E7*D7>0,E7<0),(E7-D7)/D7,(E7-D7)/D7)) -> 5.8755263 | H7: Current Ratio | I7: =+'CEE view'!C109 -> 4.2340938 | J7: =+'CEE view'!D109 -> 5.4439148 | K7: =+'CEE view'!E109 -> 3.6407583
B8: Net income/loss | C8: =+'CEE view'!C103 -> 558.47 | D8: =+'CEE view'!D103 -> 1012.555 | E8: =+'CEE view'!E103 -> 632.562 | F8: =+IF(D8*E8<=0,"N.S",IF(AND(E8*D8>0,E8<0),-(E8-D8)/D8,(E8-D8)/D8)) -> -0.37528134 | H8: ROS | I8: =+'CEE view'!C111 -> 0.036734391 | J8: =+'CEE view'!D111 -> 0.066272732 | K8: =+'CEE view'!E111 -> 0.046675016
B9: Operating Cash Flow | D9: =+'cash flow FGA'!D7 -> 1841.304 | E9: =+'cash flow FGA'!E7 -> 1444.136 | F9: =+IF(D9*E9<=0,"N.S",IF(AND(E9*D9>0,E9<0),-(E9-D9)/D9,(E9-D9)/D9)) -> -0.21569931 | H9: ROI | I9: =+'CEE view'!C113 -> 0.27896555 | J9: =+'CEE view'!D113 -> 0.40029981 | K9: =+'CEE view'!E113 -> 0.21933086
B10: Total assets | C10: =+'CEE view'!C5+'CEE view'!C13+'CEE view'!C18+'CEE view'!C46+'CEE view'!C64+'CEE view'!C68 -> 10259.901 | D10: =+'CEE view'!D5+'CEE view'!D13+'CEE view'!D18+'CEE view'!D46+'CEE view'!D64+'CEE view'!D68 -> 14385.547 | E10: =+'CEE view'!E5+'CEE view'!E13+'CEE view'!E18+'CEE view'!E46+'CEE view'!E64+'CEE view'!E68 -> 11002.446 | F10: =+IF(D10*E10<=0,"N.S",IF(AND(E10*D10>0,E10<0),-(E10-D10)/D10,(E10-D10)/D10)) -> -0.23517361 | H10: ROE | I10: =+'CEE view'!C114 -> 0.20748756 | J10: =+'CEE view'!D114 -> 0.2733578 | K10: =+'CEE view'!E114 -> 0.14586259
B11: Inventory | C11: =+'CEE view'!C13 -> 1943.708 | D11: =+'CEE view'!D13 -> 4786.515 | E11: =+'CEE view'!E13 -> 2217.839 | F11: =+IF(D11*E11<=0,"N.S",IF(AND(E11*D11>0,E11<0),-(E11-D11)/D11,(E11-D11)/D11)) -> -0.53664848
B12: Financial Debt | C12: =-(+'CEE view'!C72) -> 41.257 | D12: =-(+'CEE view'!D72) -> 45.235 | E12: =-(+'CEE view'!E72) -> 0 | F12: =+IF(D12*E12<=0,"N.S",IF(AND(E12*D12>0,E12<0),(E12-D12)/D12,(E12-D12)/D12)) -> N.S
B13: o/w short term debt | C13: =-(+'CEE view'!C73+'CEE view'!C75+'CEE view'!C77+'CEE view'!C78) -> 41.257 | D13: =-(+'CEE view'!D73+'CEE view'!D75+'CEE view'!D77+'CEE view'!D78) -> 45.235 | E13: =-(+'CEE view'!E73+'CEE view'!E75+'CEE view'!E77+'CEE view'!E78) -> 0 | F13: =+IF(D13*E13<=0,"N.S",IF(AND(E13*D13>0,E13<0),(E13-D13)/D13,(E13-D13)/D13)) -> N.S
B14: o/w m/l term debt | C14: =-(+'CEE view'!C76+'CEE view'!C74) -> 0 | D14: =-(+'CEE view'!D76+'CEE view'!D74) -> 0 | E14: =-(+'CEE view'!E76+'CEE view'!E74) -> 0 | F14: =+IF(D14*E14<=0,"N.S",IF(AND(E14*D14>0,E14<0),(E14-D14)/D14,(E14-D14)/D14)) -> N.S
B15: Net Worth | C15: =+'CEE view'!C63 -> 2691.583 | D15: =+'CEE view'!D63 -> 3704.138 | E15: =+'CEE view'!E63 -> 4336.698 | F15: =+IF(D15*E15<=0,"N.S",IF(AND(E15*D15>0,E15<0),-(E15-D15)/D15,(E15-D15)/D15)) -> 0.17077118
B16: Day receivables | C16: =+'CEE view'!C116 -> 84.47302 | D16: =+'CEE view'!D116 -> 60.539557 | E16: =+'CEE view'!E116 -> 67.295223 | F16: =+E16-D16 -> 6.7556654

Sheet cash flow FGA
B2: €/000 | D2: =+'CEE view'!D2 -> 2023 | E2: =+'CEE view'!E2 -> 2024
B4: net result | D4: =+'CEE view'!D103 -> 1012.555 | E4: =+'CEE view'!E103 -> 632.562 | G4: risultato netto | H4: net result
B5: depreciation | D5: =-('CEE view'!D94+'CEE view'!D95) -> 689.085 | E5: =-('CEE view'!E94+'CEE view'!E95) -> 768.733 | G5: dedotte le quote di ammortamento | H5: deducted the depreciation charges
B6: provisions | D6: =('CEE view'!C47-'CEE view'!D47)+('CEE view'!C28-'CEE view'!D28) -> 139.664 | E6: =('CEE view'!D47-'CEE view'!E47)+('CEE view'!D28-'CEE view'!E28) -> 42.841 | G6: a dedurre incrementi (o rilasci se con segno negativo) di fondi rischi e di fondi svalutazione crediti o trattamento di fine rapporto | H6: deducing increase (or decrease in case of negative sign) of risks provisions, bad debts provisions or severance pay (long-term provisions)
B7: OPERATING CASH FLOW | C7: (a) | D7: =SUM(D4:D6) -> 1841.304 | E7: =SUM(E4:E6) -> 1444.136 | G7: totale flusso di cassa dalle attività operative | H7: operating cash flow
B9: (increase)/decrease receivables | D9: =('CEE view'!C6+'CEE view'!C7+'CEE view'!C8+'CEE view'!C9+'CEE view'!C10+'CEE view'!C11+'CEE view'!C12+'CEE view'!C18)-('CEE view'!D6+'CEE view'!D7+'CEE view'!D8+'CEE view'!D9+'CEE view'!D10+'CEE view'!D11+'CEE view'!D12+'CEE view'!D18) -> -1006.257 | E9: =('CEE view'!D6+'CEE view'!D7+'CEE view'!D8+'CEE view'!D9+'CEE view'!D10+'CEE view'!D11+'CEE view'!D12+'CEE view'!D18)-('CEE view'!E6+'CEE view'!E7+'CEE view'!E8+'CEE view'!E9+'CEE view'!E10+'CEE view'!E11+'CEE view'!E12+'CEE view'!E18) -> 1385.296 | G9: incremento (con segno negativo) o decremento (con segno positivo) di crediti commerciali | H9: increase (in case of negative sign) or decrease (in case of positive sign) in trade receivables
B10: (increase)/decrease stock | D10: =('CEE view'!C13-'CEE view'!D13) -> -2842.807 | E10: =('CEE view'!D13-'CEE view'!E13) -> 2568.676 | G10: incremento (con segno negativo) o decremento (con segno positivo) di magazzino | H10: increase (in case of negative sign) or decrease (in case of positive sign) in stock
B11: increase/(decrease) payables | D11: =('CEE view'!C19-'CEE view'!D19)+('CEE view'!C27-'CEE view'!D27) -> 2969.449 | E11: =('CEE view'!D19-'CEE view'!E19)+('CEE view'!D27-'CEE view'!E27) -> -4013.267 | G11: incremento (con segno positivo) o decremento (con segno negativo) di debiti commerciali | H11: increase (in case of positive sign) or decrease (in case of negative sign) in trade payables
B12: working capital variation | D12: =SUM(D9:D11) -> -879.615 | E12: =SUM(E9:E11) -> -59.295 | G12: variazione di capitale circolante | H12: working capital variation
B14: (increase)/decrease fixed assets | D14: =('CEE view'!C30-'CEE view'!D30+'CEE view'!D95)+('CEE view'!C36-'CEE view'!D36+'CEE view'!D94)+('CEE view'!C42-'CEE view'!D42) -> -968.049 | E14: =('CEE view'!D30-'CEE view'!E30+'CEE view'!E95)+('CEE view'!D36-'CEE view'!E36+'CEE view'!E94)+('CEE view'!D42-'CEE view'!E42) -> -1339.961 | G14: incremento (con segno negativo) o decremento (con segno positivo) di investimenti al netto della quota di ammortamento | H14: increase (in case of negative sign) or decrease (in case of positive sign) in fixed assets, net of depreciation charge
B15: increase/(decrease) equity or reserve | D15: =('CEE view'!D53-'CEE view'!C53-'CEE view'!C62)+('CEE view'!D49-'CEE view'!C49)+('CEE view'!D61-'CEE view'!C61)+('CEE view'!D60-'CEE view'!C60) -> 0 | E15: =('CEE view'!E53-'CEE view'!D53-'CEE view'!D62)+('CEE view'!E49-'CEE view'!D49)+('CEE view'!E61-'CEE view'!D61)+('CEE view'!E60-'CEE view'!D60) -> -0.002 | G15: versamenti (con segno positivo) o prelievi (con segno negativo) di capitale sociale o di riserve in patrimonio netto | H15: cash-in (in case of positive sign) or cash-out (in case of negative sign) of share capital or reserves in the shareholders' equity
B16: extra operating activities | D16: =SUM(D14:D15) -> -968.049 | E16: =SUM(E14:E15) -> -1339.963 | G16: flusso di cassa dalle attività extra-operative | H16: extra operating activities
B18: EXTRA OPERATING CASH FLOW | C18: (b) | D18: =+D12+D16 -> -1847.664 | E18: =+E12+E16 -> -1399.258 | G18: totale flusso di cassa dalle attività extra-operative | H18: extra operating cash flow
B20: (INCREASE)/DECREASE IN FINANCIAL NEEDS | C20: (a+b) | D20: =+D18+D7 -> -6.36 | E20: =+E18+E7 -> 44.878 | G20: incremento (con segno negativo) o decremento (con segno positivo) del fabbisogno finanziario | H20: increase (in case of negative sign) or decrease (in case of positive sign) in financial needs
B22: (increase)/decrease financial debts | D22: =('CEE view'!D73+'CEE view'!D75+'CEE view'!D77+'CEE view'!D78)-('CEE view'!C73+'CEE view'!C75+'CEE view'!C77+'CEE view'!C78) -> -3.978 | E22: =('CEE view'!E73+'CEE view'!E75+'CEE view'!E77+'CEE view'!E78)-('CEE view'!D73+'CEE view'!D75+'CEE view'!D77+'CEE view'!D78) -> 45.235 | G22: incremento (con segno negativo) o decremento (con segno positivo) di debiti finanziari a breve termine | H22: increase (in case of negative sign) or decrease (in case of positive sign) of short term financial debts
B23: increase/(decrease) financial receivables (or cash) | D23: =('CEE view'!D64+'CEE view'!D68)-('CEE view'!C64+'CEE view'!C68) -> -2.382 | E23: =('CEE view'!E64+'CEE view'!E68)-('CEE view'!D64+'CEE view'!D68) -> -0.357 | G23: incremento (con segno positivo) o decremento (con segno negativo) di crediti finanziari o liquidità (cassa) | H23: increase (in case of positive sign) or decrease (in case of negative sign) of financial receivables or cash
B24: short-term debts variation | C24: (d) | D24: =SUM(D22:D23) -> -6.36 | E24: =SUM(E22:E23) -> 44.878 | G24: variazione dell'indebitamento a breve | H24: increase (in case of negative sign) or decrease (in case of positive sign) of short-term debts
B26: (increase)/decrease medium/long-term debts | C26: (e) | D26: =('CEE view'!D74+'CEE view'!D76)-('CEE view'!C74+'CEE view'!C76) -> 0 | E26: =('CEE view'!E74+'CEE view'!E76)-('CEE view'!D74+'CEE view'!D76) -> 0 | G26: variazione dell'indebitamento a medio/lungo | H26: increase (in case of negative sign) or decrease (in case of positive sign) of medium long-term debts
B27: of which new loans
B28: of which installments paid
B30: VARIATION FINANCIAL POSITION | C30: (d+e) | D30: =+D24+D26 -> -6.36 | E30: =+E24+E26 -> 44.878 | G30: variazione della posizione finanziaria | H30: financial position's variation
D32: =+D30-D20 -> -6.2403416e-12 | E32: =+E30-E20 -> -3.7942982e-12

Sheet CEE view
C2: =+'input CEE'!B1 -> 2022 | D2: =+'input CEE'!C1 -> 2023 | E2: =+'input CEE'!D1 -> 2024 | G2: ê | K2: CASH FLOW (dettaglio)
G3: valore | H3: %
A4: BALANCE SHEET
A5: 1) COMMERCIAL RECEIVABLES | C5: =SUM(C6:C12) -> 6523.065 | D5: =SUM(D6:D12) -> 7534.153 | E5: =SUM(E6:E12) -> 6144.911 | G5: =+E5-D5 -> -1389.242 | H5: =+IF(D5*E5<=0,"N.S",IF(AND(D5*E5>0,E5<0),-(E5-D5)/D5,(E5-D5)/D5)) -> -0.18439259 | K5: =-G18-G5 -> 1385.296 | L5: =+'cash flow FGA'!B9 -> (increase)/decrease receivables
A6: Trade receivables min 12 months | C6: =+'input CEE'!B47/1000 -> 4863.67 | D6: =+'input CEE'!C47/1000 -> 3807.378 | E6: =+'input CEE'!D47/1000 -> 3808.801 | G6: =+E6-D6 -> 1.423 | H6: =+IF(D6*E6<=0,"N.S",IF(AND(D6*E6>0,E6<0),-(E6-D6)/D6,(E6-D6)/D6)) -> 0.00037374802
A7: Trade receivables >12 months | C7: =+'input CEE'!B48/1000 -> 0 | D7: =+'input CEE'!C48/1000 -> 0 | E7: =+'input CEE'!D48/1000 -> 0 | G7: =+E7-D7 -> 0 | H7: =+IF(D7*E7<=0,"N.S",IF(AND(D7*E7>0,E7<0),-(E7-D7)/D7,(E7-D7)/D7)) -> N.S
A8: Receivables towards related companies | C8: =('input CEE'!B49+'input CEE'!B55)/1000 -> 1327.663 | D8: =('input CEE'!C49+'input CEE'!C55)/1000 -> 2858.485 | E8: =('input CEE'!D49+'input CEE'!D55)/1000 -> 1996.009 | G8: =+E8-D8 -> -862.476 | H8: =+IF(D8*E8<=0,"N.S",IF(AND(D8*E8>0,E8<0),-(E8-D8)/D8,(E8-D8)/D8)) -> -0.30172486
A9: Other receivables min 12 months | C9: =+'input CEE'!B63/1000 -> 7.545 | D9: =+'input CEE'!C63/1000 -> 12.594 | E9: =+'input CEE'!D63/1000 -> 33.053 | G9: =+E9-D9 -> 20.459 | H9: =+IF(D9*E9<=0,"N.S",IF(AND(D9*E9>0,E9<0),-(E9-D9)/D9,(E9-D9)/D9)) -> 1.6245037
A10: Other receivables >12 months | C10: =+'input CEE'!B64/1000 -> 0 | D10: =+'input CEE'!C64/1000 -> 0 | E10: =+'input CEE'!D64/1000 -> 0 | G10: =+E10-D10 -> 0 | H10: =+IF(D10*E10<=0,"N.S",IF(AND(D10*E10>0,E10<0),-(E10-D10)/D10,(E10-D10)/D10)) -> N.S
A11: VAT and TAX receivables -Current | C11: =('input CEE'!B57+'input CEE'!B60)/1000 -> 324.187 | D11: =('input CEE'!C57+'input CEE'!C60)/1000 -> 855.696 | E11: =('input CEE'!D57+'input CEE'!D60)/1000 -> 307.048 | G11: =+E11-D11 -> -548.648 | H11: =+IF(D11*E11<=0,"N.S",IF(AND(D11*E11>0,E11<0),-(E11-D11)/D11,(E11-D11)/D11)) -> -0.64117163
A12: VAT and TAX receivables - Deferred | C12: =('input CEE'!B58+'input CEE'!B61)/1000 -> 0 | D12: =('input CEE'!C58+'input CEE'!C61)/1000 -> 0 | E12: =('input CEE'!D58+'input CEE'!D61)/1000 -> 0 | G12: =+E12-D12 -> 0 | H12: =+IF(D12*E12<=0,"N.S",IF(AND(D12*E12>0,E12<0),-(E12-D12)/D12,(E12-D12)/D12)) -> N.S
A13: 2) STOCK | C13: =SUM(C14:C17) -> 1943.708 | D13: =SUM(D14:D17) -> 4786.515 | E13: =SUM(E14:E17) -> 2217.839 | G13: =+E13-D13 -> -2568.676 | H13: =+IF(D13*E13<=0,"N.S",IF(AND(D13*E13>0,E13<0),-(E13-D13)/D13,(E13-D13)/D13)) -> -0.53664848 | K13: =-G13 -> 2568.676 | L13: =+'cash flow FGA'!B10 -> (increase)/decrease stock
A14: Raw materials and consumables | C14: =+'input CEE'!B40/1000 -> 1943.708 | D14: =+'input CEE'!C40/1000 -> 4786.515 | E14: =+'input CEE'!D40/1000 -> 2217.839 | G14: =+E14-D14 -> -2568.676 | H14: =+IF(D14*E14<=0,"N.S",IF(AND(D14*E14>0,E14<0),-(E14-D14)/D14,(E14-D14)/D14)) -> -0.53664848
A15: Work in progress | C15: =+'input CEE'!B41/1000 -> 0 | D15: =+'input CEE'!C41/1000 -> 0 | E15: =+'input CEE'!D41/1000 -> 0 | G15: =+E15-D15 -> 0 | H15: =+IF(D15*E15<=0,"N.S",IF(AND(D15*E15>0,E15<0),-(E15-D15)/D15,(E15-D15)/D15)) -> N.S
A16: Contract work-in-progress | C16: =('input CEE'!B42+'input CEE'!B44)/1000 -> 0 | D16: =('input CEE'!C42+'input CEE'!C44)/1000 -> 0 | E16: =('input CEE'!D42+'input CEE'!D44)/1000 -> 0 | G16: =+E16-D16 -> 0 | H16: =+IF(D16*E16<=0,"N.S",IF(AND(D16*E16>0,E16<0),-(E16-D16)/D16,(E16-D16)/D16)) -> N.S
A17: Finished goods and goods for resale | C17: =+'input CEE'!B43/1000 -> 0 | D17: =+'input CEE'!C43/1000 -> 0 | E17: =+'input CEE'!D43/1000 -> 0 | G17: =+E17-D17 -> 0 | H17: =+IF(D17*E17<=0,"N.S",IF(AND(D17*E17>0,E17<0),-(E17-D17)/D17,(E17-D17)/D17)) -> N.S
A18: 3) POSITIVE PREPAYMENTS AND ACCRUALS | C18: =+'input CEE'!B79/1000 -> 28.021 | D18: =+'input CEE'!C79/1000 -> 23.19 | E18: =+'input CEE'!D79/1000 -> 27.136 | G18: =+E18-D18 -> 3.946 | H18: =+IF(D18*E18<=0,"N.S",IF(AND(D18*E18>0,E18<0),-(E18-D18)/D18,(E18-D18)/D18)) -> 0.17015955
A19: 4) (COMMERCIAL PAYABLES) | C19: =SUM(C20:C26) -> -7450.445 | D19: =SUM(D20:D26) -> -10448.799 | E19: =SUM(E20:E26) -> -6457.238 | G19: =+E19-D19 -> 3991.561 | H19: =+IF(D19*E19<=0,"N.S",IF(AND(D19*E19>0,E19<0),-(E19-D19)/D19,(E19-D19)/D19)) -> 0.38201146 | K19: =-G27-G19 -> -4013.267 | L19: =+'cash flow FGA'!B11 -> increase/(decrease) payables
A20: Suppliers, trade payables min 12 months | C20: =-'input CEE'!G52/1000 -> -947.195 | D20: =-'input CEE'!H52/1000 -> -1032.244 | E20: =-'input CEE'!I52/1000 -> -972.098 | G20: =+E20-D20 -> 60.146 | H20: =+IF(D20*E20<=0,"N.S",IF(AND(D20*E20>0,E20<0),-(E20-D20)/D20,(E20-D20)/D20)) -> 0.058267231
A21: Suppliers, trade payables >12 months | C21: =-'input CEE'!G53/1000 -> 0 | D21: =-'input CEE'!H53/1000 -> 0 | E21: =-'input CEE'!I53/1000 -> 0 | G21: =+E21-D21 -> 0 | H21: =+IF(D21*E21<=0,"N.S",IF(AND(D21*E21>0,E21<0),-(E21-D21)/D21,(E21-D21)/D21)) -> N.S
A22: Payables towards related company | C22: =-'input CEE'!G57/1000 -> -4193.285 | D22: =-'input CEE'!H57/1000 -> -8306.699 | E22: =-'input CEE'!I57/1000 -> -4233.159 | G22: =+E22-D22 -> 4073.54 | H22: =+IF(D22*E22<=0,"N.S",IF(AND(D22*E22>0,E22<0),-(E22-D22)/D22,(E22-D22)/D22)) -> 0.49039215
A23: Advances by customers | C23: =-'input CEE'!G48/1000 -> -1676.35 | D23: =-'input CEE'!H48/1000 -> -487.318 | E23: =-'input CEE'!I48/1000 -> -488.547 | G23: =+E23-D23 -> -1.229 | H23: =+IF(D23*E23<=0,"N.S",IF(AND(D23*E23>0,E23<0),-(E23-D23)/D23,(E23-D23)/D23)) -> -0.0025219672
A24: Other debts | C24: =-('input CEE'!G66+'input CEE'!G69)/1000 -> -542.429 | D24: =-('input CEE'!H66+'input CEE'!H69)/1000 -> -527.57 | E24: =-('input CEE'!I66+'input CEE'!I69)/1000 -> -499.939 | G24: =+E24-D24 -> 27.631 | H24: =+IF(D24*E24<=0,"N.S",IF(AND(D24*E24>0,E24<0),-(E24-D24)/D24,(E24-D24)/D24)) -> 0.052374093
A25: VAT and Tax payables - Current | C25: =-('input CEE'!G64)/1000 -> -91.186 | D25: =-('input CEE'!H64)/1000 -> -94.968 | E25: =-('input CEE'!I64)/1000 -> -263.495 | G25: =+E25-D25 -> -168.527 | H25: =+IF(D25*E25<=0,"N.S",IF(AND(D25*E25>0,E25<0),-(E25-D25)/D25,(E25-D25)/D25)) -> -1.7745662
A26: VAT and TAX payables - Deferred | C26: =-('input CEE'!G65)/1000 -> 0 | D26: =-('input CEE'!H65)/1000 -> 0 | E26: =-('input CEE'!I65)/1000 -> 0 | G26: =+E26-D26 -> 0 | H26: =+IF(D26*E26<=0,"N.S",IF(AND(D26*E26>0,E26<0),-(E26-D26)/D26,(E26-D26)/D26)) -> N.S
A27: 5) (NEGATIVE PREPAYMENTS AND ACCRUALS) | C27: =-'input CEE'!G74/1000 -> -71.459 | D27: =-'input CEE'!H74/1000 -> -42.554 | E27: =-'input CEE'!I74/1000 -> -20.848 | G27: =+E27-D27 -> 21.706 | H27: =+IF(D27*E27<=0,"N.S",IF(AND(D27*E27>0,E27<0),-(E27-D27)/D27,(E27-D27)/D27)) -> 0.51008131
A28: 6) (OTHER PROVISIONS - SHORT TERM) | C28: =-'input CEE'!G26/1000 -> -5.157 | D28: =-'input CEE'!H26/1000 -> -144.821 | E28: =-'input CEE'!I26/1000 -> -187.662 | G28: =+E28-D28 -> -42.841 | H28: =+IF(D28*E28<=0,"N.S",IF(AND(D28*E28>0,E28<0),-(E28-D28)/D28,(E28-D28)/D28)) -> -0.29582036 | K28: =-G47-G28 -> 42.841 | L28: =+'cash flow FGA'!B6 -> provisions
A29: A) NET WORKING CAPITAL (1+2+3+4+5+6) | C29: =+C5+C13+C18+C19+C27+C28 -> 967.733 | D29: =+D5+D13+D18+D19+D27+D28 -> 1707.684 | E29: =+E5+E13+E18+E19+E27+E28 -> 1724.138 | G29: =+E29-D29 -> 16.454 | H29: =+IF(D29*E29<=0,"N.S",IF(AND(D29*E29>0,E29<0),-(E29-D29)/D29,(E29-D29)/D29)) -> 0.0096352721
A30: 7) NET INTANGIBLE FIXED ASSETS | C30: =SUM(C31:C35) -> 12.301 | D30: =SUM(D31:D35) -> 6.565 | E30: =SUM(E31:E35) -> 0.48 | G30: =+E30-D30 -> -6.085 | H30: =+IF(D30*E30<=0,"N.S",IF(AND(D30*E30>0,E30<0),-(E30-D30)/D30,(E30-D30)/D30)) -> -0.926885
A31: Estabilishment costs | C31: =+'input CEE'!B9/1000 -> 0 | D31: =+'input CEE'!C9/1000 -> 0 | E31: =+'input CEE'!D9/1000 -> 0 | G31: =+E31-D31 -> 0 | H31: =+IF(D31*E31<=0,"N.S",IF(AND(D31*E31>0,E31<0),-(E31-D31)/D31,(E31-D31)/D31)) -> N.S
A32: Development costs | C32: =+'input CEE'!B10/1000 -> 0 | D32: =+'input CEE'!C10/1000 -> 0 | E32: =+'input CEE'!D10/1000 -> 0 | G32: =+E32-D32 -> 0 | H32: =+IF(D32*E32<=0,"N.S",IF(AND(D32*E32>0,E32<0),-(E32-D32)/D32,(E32-D32)/D32)) -> N.S
A33: Royalties | C33: =+'input CEE'!B11/1000 -> 0 | D33: =+'input CEE'!C11/1000 -> 0 | E33: =+'input CEE'!D11/1000 -> 0 | G33: =+E33-D33 -> 0 | H33: =+IF(D33*E33<=0,"N.S",IF(AND(D33*E33>0,E33<0),-(E33-D33)/D33,(E33-D33)/D33)) -> N.S
A34: Goodwill | C34: =+'input CEE'!B13/1000 -> 0 | D34: =+'input CEE'!C13/1000 -> 0 | E34: =+'input CEE'!D13/1000 -> 0 | G34: =+E34-D34 -> 0 | H34: =+IF(D34*E34<=0,"N.S",IF(AND(D34*E34>0,E34<0),-(E34-D34)/D34,(E34-D34)/D34)) -> N.S
A35: Other intangible assets (specify) | C35: =('input CEE'!B12+'input CEE'!B14+'input CEE'!B15)/1000 -> 12.301 | D35: =('input CEE'!C12+'input CEE'!C14+'input CEE'!C15)/1000 -> 6.565 | E35: =('input CEE'!D12+'input CEE'!D14+'input CEE'!D15)/1000 -> 0.48 | G35: =+E35-D35 -> -6.085 | H35: =+IF(D35*E35<=0,"N.S",IF(AND(D35*E35>0,E35<0),-(E35-D35)/D35,(E35-D35)/D35)) -> -0.926885
A36: 8) NET TANGIBLE FIXED ASSETS | C36: =SUM(C37:C41) -> 1708.439 | D36: =SUM(D37:D41) -> 1993.139 | E36: =SUM(E37:E41) -> 2551.402 | G36: =+E36-D36 -> 558.263 | H36: =+IF(D36*E36<=0,"N.S",IF(AND(D36*E36>0,E36<0),-(E36-D36)/D36,(E36-D36)/D36)) -> 0.28009236
A37: Land and buildings - Freehold | C37: =+'input CEE'!B17/1000 -> 0 | D37: =+'input CEE'!C17/1000 -> 0 | E37: =+'input CEE'!D17/1000 -> 0 | G37: =+E37-D37 -> 0 | H37: =+IF(D37*E37<=0,"N.S",IF(AND(D37*E37>0,E37<0),-(E37-D37)/D37,(E37-D37)/D37)) -> N.S
A38: Machinery | C38: =+'input CEE'!B18/1000 -> 0 | D38: =+'input CEE'!C18/1000 -> 0 | E38: =+'input CEE'!D18/1000 -> 0 | G38: =+E38-D38 -> 0 | H38: =+IF(D38*E38<=0,"N.S",IF(AND(D38*E38>0,E38<0),-(E38-D38)/D38,(E38-D38)/D38)) -> N.S
A39: Equipments | C39: =+'input CEE'!B19/1000 -> 15.477 | D39: =+'input CEE'!C19/1000 -> 19.754 | E39: =+'input CEE'!D19/1000 -> 7.307 | G39: =+E39-D39 -> -12.447 | H39: =+IF(D39*E39<=0,"N.S",IF(AND(D39*E39>0,E39<0),-(E39-D39)/D39,(E39-D39)/D39)) -> -0.63010023
A40: Advances for capital project | C40: =+'input CEE'!B21/1000 -> 0 | D40: =+'input CEE'!C21/1000 -> 0 | E40: =+'input CEE'!D21/1000 -> 0 | G40: =+E40-D40 -> 0 | H40: =+IF(D40*E40<=0,"N.S",IF(AND(D40*E40>0,E40<0),-(E40-D40)/D40,(E40-D40)/D40)) -> N.S
A41: Other tangible assets (specify) | C41: =+'input CEE'!B20/1000 -> 1692.962 | D41: =+'input CEE'!C20/1000 -> 1973.385 | E41: =+'input CEE'!D20/1000 -> 2544.095 | G41: =+E41-D41 -> 570.71 | H41: =+IF(D41*E41<=0,"N.S",IF(AND(D41*E41>0,E41<0),-(E41-D41)/D41,(E41-D41)/D41)) -> 0.28920358
...

Sheet input CEE
A1: ATTIVO | B1: 2022 | C1: 2023 | D1: 2024 | F1: PASSIVO | G1: =+B1 -> 2022 | H1: =+C1 -> 2023 | I1: =+D1 -> 2024
A3: A) CREDITI VERSO SOCI PER VERSAMENTI | B3: =+B4+B5 -> 0 | C3: =+C4+C5 -> 0 | D3: =+D4+D5 -> 0 | F3: A) PATRIMONIO NETTO CONSOLIDATO | G3: =+G4+G22 -> 2691583 | H3: =+H4+H22 -> 3704138 | I3: =+I4+I22 -> 4336698
A4: 1) Parte da richiamare | F4: 1) PATRIMONIO NETTO | G4: =+G5+G6+G7+G8+G9+G10+G18+G19+G20+G21 -> 2691583 | H4: =+H5+H6+H7+H8+H9+H10+H18+H19+H20+H21 -> 3704138 | I4: =+I5+I6+I7+I8+I9+I10+I18+I19+I20+I21 -> 4336698
A5: 2) Parte richiamata | F5: I - Capitale | G5: 1000000 | H5: 1000000 | I5: 1000000
F6: II - Riserva di sovrapprezzo azioni | G6: 0 | H6: 0 | I6: 0
A7: B) IMMOBILIZZAZIONI | B7: =SUM(B8,B16,B22) -> 1761690 | C7: =SUM(C8,C16,C22) -> 2040654 | D7: =SUM(D8,D16,D22) -> 2611882 | F7: III - Riserva di rivalutazione | G7: 0 | H7: 0 | I7: 0
A8: I - IMMOBILIZZAZIONI IMMATERIALI | B8: =SUM(B9:B15) -> 12301 | C8: =SUM(C9:C15) -> 6565 | D8: =SUM(D9:D15) -> 480 | F8: IV - Riserva legale | G8: 94072 | H8: 121994 | I8: 172623
A9: 1) Costi d'impianto e di ampliamento | B9: 0 | C9: 0 | D9: 0 | F9: V - Riserva statutarie | G9: 0 | H9: 0 | I9: 0
A10: 2) Costi di sviluppo | B10: 0 | C10: 0 | D10: 0 | F10: VI - Altre riserve distintamente indicate | G10: =SUM(G11+G12+G13+G14+G15+G16+G17) -> 2 | H10: =SUM(H11+H12+H13+H14+H15+H16+H17) -> 3 | I10: =SUM(I11+I12+I13+I14+I15+I16+I17) -> 0
A11: 3) Diritto di brevetto industriale e di utilizzo delle opere d'ingegno | B11: 0 | C11: 0 | D11: 0 | F11: Riserva straordinaria o facoltativa
A12: 4) Concessioni, licenze, marchi e diritti simili | B12: 12301 | C12: 6565 | D12: 480 | F12: Versamenti in conto futuro aumento di capitale
A13: 5) Avviamento | B13: 0 | C13: 0 | D13: 0 | F13: Versamenti a coperture perdite
A14: 6) Immobilizzazioni in corso e acconti | B14: 0 | C14: 0 | D14: 0 | F14: Riserva avanzo di fusione
A15: 7) Altre | B15: 0 | C15: 0 | D15: 0 | F15: Riserva utili su cambi
A16: II - IMMOBILIZZAZIONI MATERIALI | B16: =SUM(B17:B21) -> 1708439 | C16: =SUM(C17:C21) -> 1993139 | D16: =SUM(D17:D21) -> 2551402 | F16: Differenza da arrotondamento all'unità di euro
A17: 1) Terreni e fabbricati | B17: 0 | C17: 0 | D17: 0 | F17: Varie altre riserve | G17: 2 | H17: 3 | I17: 0
A18: 2) Impianti e macchinari | B18: 0 | C18: 0 | D18: 0 | F18: VII - Riserva per operazioni di copertura dei flussi finanziari attesi
A19: 3) Attrezzature industriali e commerciali | B19: 15477 | C19: 19754 | D19: 7307 | F19: VIII - Utile (perdite) portate a nuovo | G19: 1039039 | H19: 1569586 | I19: 2531513
A20: 4) Altri beni | B20: 1692962 | C20: 1973385 | D20: 2544095 | F20: IX - Utile (perdita) dell'esercizio | G20: 558470 | H20: 1012555 | I20: 632562
A21: 5) Immobilizzazioni in corso e acconti | B21: 0 | C21: 0 | D21: 0 | F21: X - Riserva negativa per azioni proprie in portafoglio | G21: 0 | H21: 0 | I21: 0
A22: III - IMMOBILIZZAZIONI FINANZIARIE | B22: =SUM(B23+B29+B35+B36) -> 40950 | C22: =SUM(C23+C29+C35+C36) -> 40950 | D22: =SUM(D23+D29+D35+D36) -> 60000 | F22: 2) PATRIMONIO NETTO DI TERZI | G22: =+G23+G24 -> 0 | H22: =+H23+H24 -> 0 | I22: =+I23+I24 -> 0
A23: 1) Partecipazioni | B23: =SUM(B24:B28) -> 0 | C23: =SUM(C24:C28) -> 40950 | D23: =SUM(D24:D28) -> 0 | F23: I - Capitale e riserve di terzi
A24: a) imprese controllate | B24: 0 | C24: 0 | D24: 0 | F24: II - Utile (perdita) dell'esercizio di pertinenza di terzi
A25: b) imprese collegate | B25: 0 | C25: 0 | D25: 0
A26: c) imprese controllanti | B26: 0 | C26: 0 | D26: 0 | F26: B) FONDI PER RISCHI ED ONERI | G26: =+G27+G28+G29+G30 -> 5157 | H26: =+H27+H28+H29+H30 -> 144821 | I26: =+I27+I28+I29+I30 -> 187662
A27: d) imprese sottoposte al controllo delle controllanti | B27: 0 | C27: 0 | D27: 0 | F27: 1) Per trattamento di quiescenza ed obblighi simili | G27: 0 | H27: 0 | I27: 0
A28: d-bis) altre imprese | B28: 0 | C28: 40950 | D28: 0 | F28: 2) Per imposte, anche differite | G28: 0 | H28: 0 | I28: 0
A29: 2) Crediti | B29: =SUM(B30:B34) -> 40950 | C29: =SUM(C30:C34) -> 0 | D29: =SUM(D30:D34) -> 60000 | F29: 3) Per strumenti finanziari derivati passivi | G29: 0 | H29: 0 | I29: 0
A30: a) verso imprese controllate | B30: 0 | C30: 0 | D30: 0 | F30: 4) Altri fondi | G30: 5157 | H30: 144821 | I30: 187662
A31: b) verso imprese collegate | B31: 0 | C31: 0 | D31: 0
A32: c) verso controllanti | B32: 0 | C32: 0 | D32: 0 | F32: C) TRATTAMENTO DI FINE RAPPORTO | G32: =+G33 -> 0 | H32: =+H33 -> 0 | I32: =+I33 -> 0
A33: d) verso imprese sottoposte al controllo delle controllanti | B33: 0 | C33: 0 | D33: 0 | F33: 1) Per trattamento di fine rapporto | G33: 0 | H33: 0 | I33: 0
A34: d-bis) verso altri | B34: 40950 | C34: 0 | D34: 60000
A35: 3) Altri titoli | B35: 0 | C35: 0 | D35: 0 | F35: D) DEBITI | G35: =+G69+G66+G63+G60+G57+G54+G51+G48+G45+G42+G39+G36 -> 7491702 | H35: =+H69+H66+H63+H60+H57+H54+H51+H48+H45+H42+H39+H36 -> 10494034 | I35: =+I69+I66+I63+I60+I57+I54+I51+I48+I45+I42+I39+I36 -> 6457238
A36: 4) Strumenti finanziari derivati | B36: 0 | C36: 0 | D36: 0 | F36: 1-2) Obbligazioni (convertibili e non) | G36: =+G37+G38 -> 0 | H36: =+H37+H38 -> 0 | I36: =+I37+I38 -> 0
F37: Importi esigibili entro l'esercizio successivo | G37: 0 | H37: 0 | I37: 0
A38: C) ATTIVO CIRCOLANTE | B38: =B39+B45+B65+B74 -> 8470190 | C38: =C39+C45+C65+C74 -> 12321703 | D38: =D39+D45+D65+D74 -> 8363428 | F38: Importi esigibili oltre l'esercizio successivo | G38: 0 | H38: 0 | I38: 0
A39: I - RIMANENZE | B39: =SUM(B40:B44) -> 1943708 | C39: =SUM(C40:C44) -> 4786515 | D39: =SUM(D40:D44) -> 2217839 | F39: 3) Debiti verso soci per finanziamenti | G39: =+G40+G41 -> 0 | H39: =+H40+H41 -> 0 | I39: =+I40+I41 -> 0
A40: 1) Materie prime, sussidiarie e di consumo | B40: 1943708 | C40: 4786515 | D40: 2217839 | F40: Importi esigibili entro l'esercizio successivo | G40: 0 | H40: 0 | I40: 0
A41: 2) Prodotti in corso di lavorazione e semilavorati | F41: Importi esigibili oltre l'esercizio successivo | G41: 0 | H41: 0 | I41: 0
...
